<?xml version="1.0" ?>

<robot name="2_link">
  <!-- ground -->

  <link name="ground">
    <inertial>
      <origin xyz="0 0 0"/>
      <mass value="0"/>
      <inertia
        ixx="0"
        ixy="0"
        ixz="0"
        iyy="0"
        iyz="0"
        izz="0" />
    </inertial>
  </link>

  <!-- floating base for hip x -->

  <joint name="link_1" type="revolute">

    <origin xyz="0 0 0" rpy="0 0 0"/>
    <parent link="ground"/>
    <child link="link_1"/>
    <axis xyz="0 0 1"/>
    <limit
      lower="-100"
      upper="100"
      effort="100"
      velocity="100" />

  </joint>


  <link name="link_1">

    <origin xyz="0 0 0"/>
    <inertial>
      <origin xyz="0.5 0 0"/>
      <mass value="1"/>
      <inertia
        ixx="0.0025"
        ixy="0"
        ixz="0"
        iyy="0.0846"
        iyz="0"
        izz="0.0846" />
    </inertial>

    <visual>
      <origin xyz="0.5 0 0" rpy="0 1.571 0"/>
      <geometry>
        <cylinder length="1" radius=".01"/>
      </geometry>
      <material name="mat">
        <color rgba="0 0 1 1"/>
      </material>
    </visual>

  </link>

    <joint name="fixed_joint" type="fixed">

    <origin xyz="0 0 0" rpy="0 0 0"/>
    <parent link="link_1"/>
    <child link="fixed_link"/>
    <axis xyz="0 0 1"/>
    <limit
      lower="-100"
      upper="100"
      effort="100"
      velocity="100" />

  </joint>

  <link name="fixed_link">

    <origin xyz="0 0 0"/>
    <inertial>
      <origin xyz="0.5 0 0"/>
      <mass value="1"/>
      <inertia
        ixx="0.0025"
        ixy="0"
        ixz="0"
        iyy="0.0846"
        iyz="0"
        izz="0.0846" />
    </inertial>

    <visual>
      <origin xyz="0.5 0 0" rpy="0 1.571 0"/>
      <geometry>
        <sphere radius=".05"/>
      </geometry>
      <material name="mat">
        <color rgba="0 0 1 1"/>
      </material>
    </visual>

  </link>


  <joint name="link_2" type="revolute">
    <origin xyz="1 0 0" rpy="0 0 0"/>
    <parent link="fixed_link"/>
    <child link="link_2"/>
    <axis xyz="0 0 1"/>
    <limit
      lower="-100"
      upper="100"
      effort="100"
      velocity="100" />
  </joint>

  <link name="link_2">

    <origin xyz="0 0 0"/>
    <inertial>
      <origin xyz="0.5 0 0"/>
      <mass value="1"/>
      <inertia
        ixx="0.0025"
        ixy="0"
        ixz="0"
        iyy="0.0846"
        iyz="0"
        izz="0.0846" />
    </inertial>

    <visual>
      <origin xyz="0.5 0 0" rpy="0 1.571 0"/>
      <geometry>
        <cylinder length="1" radius=".01"/>
      </geometry>
      <material name="mat">
        <color rgba="0 0 1 1"/>
      </material>
    </visual>

  </link>



</robot>
