<?xml version="1.0" ?>
<robot name="nugus">
  <joint name="right_shoulder_pitch" type="revolute">
    <parent link="torso"/>
    <child link="right_shoulder"/>
    <origin rpy="-1.57079  0       1.57079" xyz="0.005 -0.115  0.18"/>
    <axis xyz="1  0  0"/>
    <limit effort="7.3" lower="-3.14159265359" upper="3.14159265359" velocity="8.16814"/>
  </joint>
  <joint name="left_shoulder_pitch" type="revolute">
    <parent link="torso"/>
    <child link="left_shoulder"/>
    <origin rpy="-1.57079  0       1.57079" xyz="0.005  0.115  0.18"/>
    <axis xyz="1  0  0"/>
    <limit effort="7.3" lower="-3.14159265359" upper="3.14159265359" velocity="8.16814"/>
  </joint>
  <joint name="right_shoulder_roll" type="revolute">
    <parent link="right_shoulder"/>
    <child link="right_upper_arm"/>
    <origin rpy="1.57079  0       0" xyz="-0.015  0     0.005"/>
    <axis xyz="0  0  1"/>
    <limit effort="7.3" lower="-3.14159265359" upper="3.14159265359" velocity="8.16814"/>
  </joint>
  <joint name="left_shoulder_roll" type="revolute">
    <parent link="left_shoulder"/>
    <child link="left_upper_arm"/>
    <origin rpy="1.57079  0       0" xyz="0.015  0     0.005"/>
    <axis xyz="0  0  1"/>
    <limit effort="7.3" lower="-3.14159265359" upper="3.14159265359" velocity="8.16814"/>
  </joint>
  <joint name="right_elbow_pitch" type="revolute">
    <parent link="right_upper_arm"/>
    <child link="right_lower_arm"/>
    <origin rpy="0  0  0" xyz="0.01 -0.19  0.04"/>
    <axis xyz="1  0  0"/>
    <limit effort="7.3" lower="-3.14159265359" upper="3.14159265359" velocity="8.16814"/>
  </joint>
  <joint name="left_elbow_pitch" type="revolute">
    <parent link="left_upper_arm"/>
    <child link="left_lower_arm"/>
    <origin rpy="0  0  0" xyz="-0.01    -0.19     0.03999"/>
    <axis xyz="1  0  0"/>
    <limit effort="7.3" lower="-3.14159265359" upper="3.14159265359" velocity="8.16814"/>
  </joint>
  <joint name="right_hip_yaw" type="revolute">
    <parent link="torso"/>
    <child link="right_hip_yaw"/>
    <origin rpy="0 0 0" xyz="0    -0.055  0"/>
    <axis xyz="0  0  1"/>
    <limit effort="10.0" lower="-3.14159265359" upper="3.14159265359" velocity="5.75959"/>
  </joint>
  <joint name="left_hip_yaw" type="revolute">
    <parent link="torso"/>
    <child link="left_hip_yaw"/>
    <origin rpy="0 0 0" xyz="0 0.055 0"/>
    <axis xyz="0  0  1"/>
    <limit effort="10.0" lower="-3.14159265359" upper="3.14159265359" velocity="5.75959"/>
  </joint>  
  <joint name="right_hip_roll" type="revolute">
    <parent link="right_hip_yaw"/>
    <child link="right_hip_roll"/>
    <origin rpy="0  1.571  0" xyz="0 0 -0.06"/>
    <axis xyz="0 0 1"/>
    <limit effort="10.0" lower="-3.14159265359" upper="3.14159265359" velocity="5.75959"/>
  </joint>
  <joint name="left_hip_roll" type="revolute">
    <parent link="left_hip_yaw"/>
    <child link="left_hip_roll"/>
    <origin rpy="0  1.571  0" xyz="0 0 -0.06"/>
    <axis xyz="0 0 1"/>
    <limit effort="10.0" lower="-3.14159265359" upper="3.14159265359" velocity="5.75959"/>
  </joint>
  <joint name="right_hip_pitch" type="revolute">
    <parent link="right_hip_roll"/>
    <child link="right_upper_leg"/>
    <origin rpy="-1.571 0 0" xyz="0 0 0"/>
    <axis xyz="0 0 1"/>
    <limit effort="10.0" lower="-3.14159265359" upper="3.14159265359" velocity="5.75959"/>
  </joint>
  <joint name="left_hip_pitch" type="revolute">
    <parent link="left_hip_roll"/>
    <child link="left_upper_leg"/>
    <origin rpy="-1.571 0 0" xyz="0 0 0"/>
    <axis xyz="0 0 1"/>
    <limit effort="10.0" lower="-3.14159265359" upper="3.14159265359" velocity="5.75959"/>
  </joint>
  <joint name="right_knee_pitch" type="revolute">
    <parent link="right_upper_leg"/>
    <child link="right_lower_leg"/>
    <origin rpy="0 0 0" xyz="0.2 0 0"/>
    <axis xyz="0 0 1"/>
    <limit effort="10.0" lower="-3.14159265359" upper="3.14159265359" velocity="5.75959"/>
  </joint>
  <joint name="left_knee_pitch" type="revolute">
    <parent link="left_upper_leg"/>
    <child link="left_lower_leg"/>
    <origin rpy="0 0 0" xyz="0.2 0 0"/>
    <axis xyz="0 0 1"/>
    <limit effort="10.0" lower="-3.14159265359" upper="3.14159265359" velocity="5.75959"/>
  </joint>
  <joint name="right_ankle_pitch" type="revolute">
    <parent link="right_lower_leg"/>
    <child link="right_ankle"/>
    <origin rpy=" 0 0 0" xyz="0.2 0 0"/>
    <axis xyz="0 0 1"/>
    <limit effort="10.0" lower="-3.14159265359" upper="3.14159265359" velocity="5.75959"/>
  </joint>
  <joint name="left_ankle_pitch" type="revolute">
    <parent link="left_lower_leg"/>
    <child link="left_ankle"/>
    <origin rpy="0 0 0" xyz="0.2 0 0"/>
    <axis xyz="0 0 1"/>
    <limit effort="10.0" lower="-3.14159265359" upper="3.14159265359" velocity="5.75959"/>
  </joint>
  <joint name="right_ankle_roll" type="revolute">
    <parent link="right_ankle"/>
    <child link="right_foot"/>
    <origin rpy="1.571 0 0" xyz="0 0 0"/>
    <axis xyz="0 0 1"/>
    <limit effort="10.0" lower="-3.14159265359" upper="3.14159265359" velocity="5.75959"/>
  </joint>
  <joint name="left_ankle_roll" type="revolute">
    <parent link="left_ankle"/>
    <child link="left_foot"/>
    <origin rpy="1.571 0 0" xyz="0 0 0"/>
    <axis xyz="0 0 1"/>
    <limit effort="10.0" lower="-3.14159265359" upper="3.14159265359" velocity="5.75959"/>
  </joint>
  <joint name="neck_yaw" type="revolute">
    <parent link="torso"/>
    <child link="neck"/>
    <origin rpy="0       0       1.57079" xyz="0    0    0.26"/>
    <axis xyz="0  0  1"/>
    <limit effort="7.3" lower="-3.14159265359" upper="3.14159265359" velocity="8.16814"/>
  </joint>
  <joint name="head_pitch" type="revolute">
    <parent link="neck"/>
    <child link="head"/>
    <origin rpy="0  0  0" xyz="0  0  0"/>
    <axis xyz="1  0  0"/>
    <limit effort="7.3" lower="-3.14159265359" upper="3.14159265359" velocity="8.16814"/>
  </joint>
  <link name="torso">
    <inertial>
      <mass value="0"/>
      <origin rpy="0  0  1.571" xyz="0 0 0.15"/>
    <inertia ixx="0.1" ixy="0.0" ixz="0.0" iyy="0.1" iyz="0.0" izz="0.1"/>
    </inertial>
    <collision name="torso_collision">
      <origin rpy="0       0       1.57079" xyz="0  0  0"/>
      <geometry>
        <mesh filename="mesh/torso.stl" scale="1 1 1"/>
      </geometry>
    </collision>
    <visual name="torso_visual">
      <origin rpy="0       0       1.57079" xyz="0  0  0"/>
      <geometry>
        <mesh filename="mesh/torso.stl" scale="1 1 1"/>
      </geometry>
    </visual>
  </link>
  <link name="right_shoulder">
    <inertial>
      <mass value="0"/>
      <origin rpy="0  0  0" xyz="-0.0075 0 0"/>
    <inertia ixx="0.1" ixy="0.0" ixz="0.0" iyy="0.1" iyz="0.0" izz="0.1"/>
    </inertial>
    <collision name="right_shoulder_collision">
      <origin rpy="0  0  0" xyz="0  0  0"/>
      <geometry>
        <mesh filename="mesh/right_shoulder.stl" scale="1 1 1"/>
      </geometry>
    </collision>
    <visual name="right_shoulder_visual">
      <origin rpy="0  0  0" xyz="0  0  0"/>
      <geometry>
        <mesh filename="mesh/right_shoulder.stl" scale="1 1 1"/>
      </geometry>
    </visual>
  </link>
  <link name="left_shoulder">
    <inertial>
      <mass value="0"/>
      <origin rpy="0  0  0" xyz="0.0075 0 0"/>
    <inertia ixx="0.1" ixy="0.0" ixz="0.0" iyy="0.1" iyz="0.0" izz="0.1"/>
    </inertial>
    <collision name="left_shoulder_collision">
      <origin rpy="0  0  0" xyz="0  0  0"/>
      <geometry>
        <mesh filename="mesh/left_shoulder.stl" scale="1 1 1"/>
      </geometry>
    </collision>
    <visual name="left_shoulder_visual">
      <origin rpy="0  0  0" xyz="0  0  0"/>
      <geometry>
        <mesh filename="mesh/left_shoulder.stl" scale="1 1 1"/>
      </geometry>
    </visual>
  </link>
  <link name="right_upper_arm">
    <inertial>
      <mass value="0"/>
      <origin rpy="0  0  0" xyz="-0.00047 -0.00048 -0.04785"/>
    <inertia ixx="0.1" ixy="0.0" ixz="0.0" iyy="0.1" iyz="0.0" izz="0.1"/>
    </inertial>
    <collision name="right_upper_arm_collision">
      <origin rpy="0  0  0" xyz="0  0  0"/>
      <geometry>
        <mesh filename="mesh/right_upper_arm.stl" scale="1 1 1"/>
      </geometry>
    </collision>
    <visual name="right_upper_arm_visual">
      <origin rpy="0  0  0" xyz="0  0  0"/>
      <geometry>
        <mesh filename="mesh/right_upper_arm.stl" scale="1 1 1"/>
      </geometry>
    </visual>
  </link>
  <link name="left_upper_arm">
    <inertial>
      <mass value="0"/>
      <origin rpy="0  0  0" xyz="0 0 0"/>
    <inertia ixx="0.1" ixy="0.0" ixz="0.0" iyy="0.1" iyz="0.0" izz="0.1"/>
    </inertial>
    <collision name="left_upper_arm_collision">
      <origin rpy="0  0  0" xyz="0  0  0"/>
      <geometry>
        <mesh filename="mesh/left_upper_arm.stl" scale="1 1 1"/>
      </geometry>
    </collision>
    <visual name="left_upper_arm_visual">
      <origin rpy="0  0  0" xyz="0  0  0"/>
      <geometry>
        <mesh filename="mesh/left_upper_arm.stl" scale="1 1 1"/>
      </geometry>
    </visual>
  </link>
  <link name="right_lower_arm">
    <inertial>
      <mass value="0"/>
      <origin rpy="0  0  0" xyz="0.05336 -0.00081  0.0006"/>
    <inertia ixx="0.1" ixy="0.0" ixz="0.0" iyy="0.1" iyz="0.0" izz="0.1"/>
    </inertial>
    <collision name="right_lower_arm_collision">
      <origin rpy="0  0  0" xyz="0  0  0"/>
      <geometry>
        <mesh filename="mesh/right_lower_arm.stl" scale="1 1 1"/>
      </geometry>
    </collision>
    <visual name="right_lower_arm_visual">
      <origin rpy="0  0  0" xyz="0  0  0"/>
      <geometry>
        <mesh filename="mesh/right_lower_arm.stl" scale="1 1 1"/>
      </geometry>
    </visual>
  </link>
  <link name="left_lower_arm">
    <inertial>
      <mass value="0"/>
      <origin rpy="0  0  0" xyz="0.05336 -0.00081  0.0006"/>
    <inertia ixx="0.1" ixy="0.0" ixz="0.0" iyy="0.1" iyz="0.0" izz="0.1"/>
    </inertial>
    <collision name="left_lower_arm_collision">
      <origin rpy="0  0  0" xyz="0  0  0"/>
      <geometry>
        <mesh filename="mesh/left_lower_arm.stl" scale="1 1 1"/>
      </geometry>
    </collision>
    <visual name="left_lower_arm_visual">
      <origin rpy="0  0  0" xyz="0  0  0"/>
      <geometry>
        <mesh filename="mesh/left_lower_arm.stl" scale="1 1 1"/>
      </geometry>
    </visual>
  </link>
  <link name="right_hip_yaw">
    <inertial>
      <mass value="0.067"/>
      <origin rpy="0  0  0" xyz="0 0 -0.03"/>
    <inertia ixx="0.1" ixy="0.0" ixz="0.0" iyy="0.1" iyz="0.0" izz="0.1"/>
    </inertial>
    <collision name="right_hip_yaw_collision">
      <origin rpy="0  0  1.571" xyz="0  0  0"/>
      <geometry>
        <mesh filename="mesh/right_hip_yaw.stl" scale="1 1 1"/>
      </geometry>
    </collision>
    <visual name="right_hip_yaw_visual">
      <origin rpy="0  0  1.571" xyz="0  0  0"/>
      <geometry>
        <mesh filename="mesh/right_hip_yaw.stl" scale="1 1 1"/>
      </geometry>
    </visual> 
  </link>
  <link name="left_hip_yaw">
    <inertial>
      <mass value="0.067"/>
      <origin rpy="0  0  0" xyz="0 0 -0.03"/>
    <inertia ixx="0.1" ixy="0.0" ixz="0.0" iyy="0.1" iyz="0.0" izz="0.1"/>
    </inertial>
    <collision name="left_hip_yaw_collision">
      <origin rpy="0  0  1.571" xyz="0  0  0"/>
      <geometry>
        <mesh filename="mesh/left_hip_yaw.stl" scale="1 1 1"/>
      </geometry>
    </collision>
    <visual name="left_hip_yaw_visual">
      <origin rpy="0  0  1.571" xyz="0  0  0"/>
      <geometry>
        <mesh filename="mesh/left_hip_yaw.stl" scale="1 1 1"/>
      </geometry>
    </visual>
  </link>
  <link name="right_hip_roll">
    <inertial>
      <mass value="0.306"/>
      <origin rpy="0 0 0" xyz="0 0 0"/>
    <inertia ixx="0.1" ixy="0.0" ixz="0.0" iyy="0.1" iyz="0.0" izz="0.1"/>
    </inertial>
    <collision name="right_hip_roll_collision">
      <origin rpy="-1.571 0 1.571" xyz="0  0  0"/>
      <geometry>
        <mesh filename="mesh/right_hip_roll.stl" scale="1 1 1"/>
      </geometry>
    </collision>
    <visual name="right_hip_roll_visual">
      <origin rpy="-1.571 0 1.571" xyz="0  0  0"/>
      <geometry>
        <mesh filename="mesh/right_hip_roll.stl" scale="1 1 1"/>
      </geometry>
    </visual>
  </link>
  <link name="left_hip_roll">
    <inertial>
      <mass value="0.306"/>
      <origin rpy="0 0 0" xyz="0 0 0"/>
    <inertia ixx="0.1" ixy="0.0" ixz="0.0" iyy="0.1" iyz="0.0" izz="0.1"/>
    </inertial>
    <collision name="left_hip_roll_collision">
      <origin rpy="-1.571 0 1.571" xyz="0  0  0"/>
      <geometry>
        <mesh filename="mesh/left_hip_roll.stl" scale="1 1 1"/>
      </geometry>
    </collision>
    <visual name="left_hip_roll_visual">
      <origin rpy="-1.571 0 1.571" xyz="0  0  0"/>
      <geometry>
        <mesh filename="mesh/left_hip_roll.stl" scale="1 1 1"/>
      </geometry>
    </visual>
  </link>
  <link name="right_upper_leg">
    <inertial>
      <mass value="0.387"/>
      <origin rpy="0 0 0" xyz="0.1 0 0"/>
    <inertia ixx="0.1" ixy="0.0" ixz="0.0" iyy="0.1" iyz="0.0" izz="0.1"/>
    </inertial>
    <collision name="right_upper_leg_collision">
      <origin rpy="0 -1.571 0" xyz="0 0 0"/>
      <geometry>
        <mesh filename="mesh/right_upper_leg.stl" scale="1 1 1"/>
      </geometry>
    </collision>
    <visual name="right_upper_leg_visual">
      <origin rpy="0 -1.571 0" xyz="-0.01 -0.01 0"/>
      <geometry>
        <mesh filename="mesh/right_upper_leg.stl" scale="1 1 1"/>
      </geometry>
    </visual>
  </link>
  <link name="left_upper_leg">
    <inertial>
      <mass value="0.387"/>
      <origin rpy="0 0 0" xyz="0.1 0 0"/>
    <inertia ixx="0.1" ixy="0.0" ixz="0.0" iyy="0.1" iyz="0.0" izz="0.1"/>
    </inertial>
    <collision name="left_upper_leg_collision">
      <origin rpy="0 -1.571 0" xyz="0 0 0"/>
      <geometry>
        <mesh filename="mesh/left_upper_leg.stl" scale="1 1 1"/>
      </geometry>
    </collision>
    <visual name="left_upper_leg_visual">
      <origin rpy="0 -1.571 0" xyz="-0.01 -0.01 0"/>
      <geometry>
        <mesh filename="mesh/left_upper_leg.stl" scale="1 1 1"/>
      </geometry>
    </visual>
  </link>
  <link name="right_lower_leg">
    <inertial>
      <mass value="0.177"/>
      <origin rpy="0 0 0" xyz="0.1 0 0"/>
    <inertia ixx="0.1" ixy="0.0" ixz="0.0" iyy="0.1" iyz="0.0" izz="0.1"/>
    </inertial>
    <collision name="right_lower_leg_collision">
      <origin rpy="0 -1.571 0" xyz="0  0  0"/>
      <geometry>
        <mesh filename="mesh/right_lower_leg.stl" scale="1 1 1"/>
      </geometry>
    </collision>
    <visual name="right_lower_leg_visual">
      <origin rpy="0 -1.571 0" xyz="0  0  0"/>
      <geometry>
        <mesh filename="mesh/right_lower_leg.stl" scale="1 1 1"/>
      </geometry>
    </visual>
  </link>
  <link name="left_lower_leg">
    <inertial>
      <mass value="0.177"/>
      <origin rpy="0 0 0" xyz="0.1 0 0"/>
    <inertia ixx="0.1" ixy="0.0" ixz="0.0" iyy="0.1" iyz="0.0" izz="0.1"/>
    </inertial>
    <collision name="left_lower_leg_collision">
      <origin rpy="0 -1.571 0" xyz="0  0  0"/>
      <geometry>
        <mesh filename="mesh/left_lower_leg.stl" scale="1 1 1"/>
      </geometry>
    </collision>
    <visual name="left_lower_leg_visual">
      <origin rpy="0 -1.571 0" xyz="0  0  0"/>
      <geometry>
        <mesh filename="mesh/left_lower_leg.stl" scale="1 1 1"/>
      </geometry>
    </visual>
  </link>
  <link name="right_ankle">
    <inertial>
      <mass value="0.306"/>
      <origin rpy="0 0 0" xyz="0 0 0"/>
    <inertia ixx="0.1" ixy="0.0" ixz="0.0" iyy="0.1" iyz="0.0" izz="0.1"/>
    </inertial>
    <collision name="right_ankle_collision">
      <origin rpy="0 1.571 0" xyz="0  0  0"/>
      <geometry>
        <mesh filename="mesh/right_ankle.stl" scale="1 1 1"/>
      </geometry>
    </collision>
    <visual name="right_ankle_visual">
      <origin rpy="0 1.571 0" xyz="0  0  0"/>
      <geometry>
        <mesh filename="mesh/right_ankle.stl" scale="1 1 1"/>
      </geometry>
    </visual>
  </link>
  <link name="left_ankle">
    <inertial>
      <mass value="0.306"/>
      <origin rpy="0 0 0" xyz="0 0 0"/>
    <inertia ixx="0.1" ixy="0.0" ixz="0.0" iyy="0.1" iyz="0.0" izz="0.1"/>
    </inertial>
    <collision name="left_ankle_collision">
      <origin rpy="0 1.571 0" xyz="0  0  0"/>
      <geometry>
        <mesh filename="mesh/left_ankle.stl" scale="1 1 1"/>
      </geometry>
    </collision>
    <visual name="left_ankle_visual">
      <origin rpy="0 1.571 0" xyz="0  0  0"/>
      <geometry>
        <mesh filename="mesh/left_ankle.stl" scale="1 1 1"/>
      </geometry>
    </visual>
  </link>
  <link name="right_foot">
    <inertial>
      <mass value="0.205"/>
      <origin rpy="0 0 0" xyz="0 0 0"/>
    <inertia ixx="0.1" ixy="0.0" ixz="0.0" iyy="0.1" iyz="0.0" izz="0.1"/>
    </inertial>
    <collision name="right_foot_collision">
      <origin rpy="-1.571 0 1.571" xyz="-0.01 0 -0.04"/>
      <geometry>
        <mesh filename="mesh/right_foot.stl" scale="1 1 1"/>
      </geometry>
    </collision>
    <visual name="right_foot_visual">
      <origin rpy="-1.571 0 1.571" xyz="-0.01 0 -0.04"/>
      <geometry>
        <mesh filename="mesh/right_foot.stl" scale="1 1 1"/>
      </geometry>
    </visual>
  </link>
  <link name="left_foot">
    <inertial>
      <mass value="0.205"/>
      <origin rpy="0 0 0" xyz="0 0 0"/>
    <inertia ixx="0.1" ixy="0.0" ixz="0.0" iyy="0.1" iyz="0.0" izz="0.1"/>
    </inertial>
    <collision name="left_foot_collision">
      <origin rpy="-1.571 0 1.571" xyz="-0.01 0 -0.04"/>
      <geometry>
        <mesh filename="mesh/left_foot.stl" scale="1 1 1"/>
      </geometry>
    </collision>
    <visual name="left_foot_visual">
      <origin rpy="-1.571 0 1.571" xyz="-0.01 0 -0.04"/>
      <geometry>
        <mesh filename="mesh/left_foot.stl" scale="1 1 1"/>
      </geometry>
    </visual>
  </link>
  <link name="neck">
    <inertial>
      <mass value="0"/>
      <origin rpy="0  0  0" xyz="-0.00603 -0.0016   0.24115"/>
    <inertia ixx="0.1" ixy="0.0" ixz="0.0" iyy="0.1" iyz="0.0" izz="0.1"/>
    </inertial>
    <collision name="neck_collision">
      <origin rpy="0  0  0" xyz="0  0  0"/>
      <geometry>
        <mesh filename="mesh/neck.stl" scale="1 1 1"/>
      </geometry>
    </collision>
    <visual name="neck_visual">
      <origin rpy="0  0  0" xyz="0  0  0"/>
      <geometry>
        <mesh filename="mesh/neck.stl" scale="1 1 1"/>
      </geometry>
    </visual>
  </link>
  <link name="head">
    <inertial>
      <mass value="4.2530"/>
      <origin rpy="0  0  0" xyz="0 0 -0.11"/>
    <inertia ixx="0.1" ixy="0.0" ixz="0.0" iyy="0.1" iyz="0.0" izz="0.1"/>
    </inertial>
    <collision name="head_collision">
      <origin rpy="0  0  0" xyz="0  0  0"/>
      <geometry>
        <mesh filename="mesh/head.stl" scale="1 1 1"/>
      </geometry>
    </collision>
    <visual name="head_visual">
      <origin rpy="0  0  0" xyz="0  0  0"/>
      <geometry>
        <mesh filename="mesh/head.stl" scale="1 1 1"/>
      </geometry>
    </visual>
  </link>
</robot>
